Workbook

Sheet Assumptions
A1: KutumbKosh — Business Growth Plan v2
A2: Updated: ₹499/yr pricing + B2B channel + Marketing
A4: PRICING
A5: Annual price (Pro) | B5: 499 | C5: ₹499/year
A6: Monthly price (Pro) | B6: 79 | C6: ₹79/month
A7: Effective monthly (annual) | B7: =B5/12
A8: B2B per-seat annual price | B8: 399 | C8: Discounted bulk rate for CA/advisor referrals
A10: USER GROWTH
A11: Launch signups (M1) | B11: 400 | C11: Pre-launch waitlist + social
A12: Organic monthly growth rate | B12: 0.2 | C12: 20% MoM from SEO, referrals, content
A13: Monthly churn rate | B13: 0.03 | C13: 3% monthly churn
A14: B2B onboarding start month | B14: 4 | C14: CA/advisor channel kicks in at M4
A15: B2B monthly new users (initial) | B15: 100 | C15: ~2-3 CAs onboarding clients
A16: B2B user growth rate | B16: 0.15 | C16: 15% MoM growth in B2B channel
A18: CONVERSION
A19: Initial D2C conversion rate | B19: 0.03 | C19: 3% of organic users convert to Pro
A20: Monthly conversion uplift | B20: 0.002 | C20: +0.2% per month as trust builds
A21: Max D2C conversion rate | B21: 0.1 | C21: Cap at 10%
A22: B2B conversion rate | B22: 0.25 | C22: 25% — CA-referred users convert much higher
A23: Monetization start month | B23: 3 | C23: Payments go live at M3
A25: PAYMENT GATEWAY
A26: Razorpay base fee | B26: 0.02 | C26: 2% per transaction
A27: Razorpay subscription add-on | B27: 0.01 | C27: 1% for recurring
A28: GST on gateway fees | B28: 0.18 | C28: 18% GST
A29: UPI payment share | B29: 0.6 | C29: 60% pay via UPI (lower effective fee)
A30: Blended gateway cost | B30: =(1-B29)*(B26+B27)*(1+B28) | C30: Effective rate after UPI discount
A32: INFRASTRUCTURE (Monthly)
A33: Supabase Pro | B33: 2100 | C33: ~$25/mo
A34: Vercel Pro | B34: 1700 | C34: ~$20/mo
A35: Resend email | B35: 0 | C35: Free tier (3K emails/mo)
A36: Domain + DNS | B36: 100 | C36: ~₹1200/year ÷ 12
A37: Google Workspace | B37: 250 | C37: 1 user
A38: Misc (monitoring, backups) | B38: 500 | C38: Error tracking, backups
A39: Total infra | B39: =SUM(B33:B38)
A41: MARKETING (starts M3)
A42: Marketing start month | B42: 3 | C42: Start spending post M3
A43: Initial monthly budget | B43: 5000 | C43: Google Ads, social media
A44: Monthly budget increase | B44: 2000 | C44: Increase ₹2K/month as revenue grows
A45: Max monthly budget | B45: 25000 | C45: Cap monthly marketing spend
A46: B2B partnership costs | B46: 2000 | C46: Commission/incentives for CA referrals
...

Sheet Growth Model
A1: KutumbKosh — 18-Month Growth Model (v2)
A3: Month | B3: M1 | C3: M2 | D3: M3 | E3: M4 | F3: M5 | G3: M6 | H3: M7 | I3: M8 | J3: M9 | K3: M10 | L3: M11 | M3: M12 | N3: M13 | O3: M14 | P3: M15 | Q3: M16 | R3: M17 | S3: M18
A4: USER METRICS
A5: New organic signups | B5: =Assumptions!B11 | C5: =ROUND(B5*(1+Assumptions!B12),0) | D5: =ROUND(C5*(1+Assumptions!B12),0) | E5: =ROUND(D5*(1+Assumptions!B12),0) | F5: =ROUND(E5*(1+Assumptions!B12),0) | G5: =ROUND(F5*(1+Assumptions!B12),0) | H5: =ROUND(G5*(1+Assumptions!B12),0) | I5: =ROUND(H5*(1+Assumptions!B12),0) | J5: =ROUND(I5*(1+Assumptions!B12),0) | K5: =ROUND(J5*(1+Assumptions!B12),0) | L5: =ROUND(K5*(1+Assumptions!B12),0) | M5: =ROUND(L5*(1+Assumptions!B12),0) | N5: =ROUND(M5*(1+Assumptions!B12),0) | O5: =ROUND(N5*(1+Assumptions!B12),0) | P5: =ROUND(O5*(1+Assumptions!B12),0) | Q5: =ROUND(P5*(1+Assumptions!B12),0) | R5: =ROUND(Q5*(1+Assumptions!B12),0) | S5: =ROUND(R5*(1+Assumptions!B12),0)
A6: New B2B signups | B6: 0 | C6: 0 | D6: 0 | E6: =Assumptions!B15 | F6: =ROUND(E6*(1+Assumptions!B16),0) | G6: =ROUND(F6*(1+Assumptions!B16),0) | H6: =ROUND(G6*(1+Assumptions!B16),0) | I6: =ROUND(H6*(1+Assumptions!B16),0) | J6: =ROUND(I6*(1+Assumptions!B16),0) | K6: =ROUND(J6*(1+Assumptions!B16),0) | L6: =ROUND(K6*(1+Assumptions!B16),0) | M6: =ROUND(L6*(1+Assumptions!B16),0) | N6: =ROUND(M6*(1+Assumptions!B16),0) | O6: =ROUND(N6*(1+Assumptions!B16),0) | P6: =ROUND(O6*(1+Assumptions!B16),0) | Q6: =ROUND(P6*(1+Assumptions!B16),0) | R6: =ROUND(Q6*(1+Assumptions!B16),0) | S6: =ROUND(R6*(1+Assumptions!B16),0)
A7: Total new signups | B7: =B5+B6 | C7: =C5+C6 | D7: =D5+D6 | E7: =E5+E6 | F7: =F5+F6 | G7: =G5+G6 | H7: =H5+H6 | I7: =I5+I6 | ... S7: =S5+S6
A8: Churned users | B8: 0 | C8: =ROUND(B9*Assumptions!B13,0) | D8: =ROUND(C9*Assumptions!B13,0) | E8: =ROUND(D9*Assumptions!B13,0) | F8: =ROUND(E9*Assumptions!B13,0) | G8: =ROUND(F9*Assumptions!B13,0) | H8: =ROUND(G9*Assumptions!B13,0) | I8: =ROUND(H9*Assumptions!B13,0) | J8: =ROUND(I9*Assumptions!B13,0) | K8: =ROUND(J9*Assumptions!B13,0) | L8: =ROUND(K9*Assumptions!B13,0) | M8: =ROUND(L9*Assumptions!B13,0) | N8: =ROUND(M9*Assumptions!B13,0) | O8: =ROUND(N9*Assumptions!B13,0) | P8: =ROUND(O9*Assumptions!B13,0) | Q8: =ROUND(P9*Assumptions!B13,0) | R8: =ROUND(Q9*Assumptions!B13,0) | S8: =ROUND(R9*Assumptions!B13,0)
A9: Cumulative users | B9: =B7 | C9: =B9+C7-C8 | D9: =C9+D7-D8 | E9: =D9+E7-E8 | F9: =E9+F7-F8 | G9: =F9+G7-G8 | H9: =G9+H7-H8 | I9: =H9+I7-I8 | J9: =I9+J7-J8 | ... S9: =R9+S7-S8
A10: MAU (80% of total) | B10: =ROUND(B9*0.8,0) | C10: =ROUND(C9*0.8,0) | D10: =ROUND(D9*0.8,0) | E10: =ROUND(E9*0.8,0) | F10: =ROUND(F9*0.8,0) | G10: =ROUND(G9*0.8,0) | H10: =ROUND(H9*0.8,0) | I10: =ROUND(I9*0.8,0) | ... S10: =ROUND(S9*0.8,0)
A12: CONVERSION & REVENUE
A13: D2C conversion rate | B13: 0 | C13: 0 | D13: =MIN(Assumptions!B19+((3-Assumptions!B23)*Assumptions!B20),Assumptions!B21) | E13: =MIN(Assumptions!B19+((4-Assumptions!B23)*Assumptions!B20),Assumptions!B21) | F13: =MIN(Assumptions!B19+((5-Assumptions!B23)*Assumptions!B20),Assumptions!B21) | G13: =MIN(Assumptions!B19+((6-Assumptions!B23)*Assumptions!B20),Assumptions!B21) | H13: =MIN(Assumptions!B19+((7-Assumptions!B23)*Assumptions!B20),Assumptions!B21) | I13: =MIN(Assumptions!B19+((8-Assumptions!B23)*Assumptions!B20),Assumptions!B21) | J13: =MIN(Assumptions!B19+((9-Assumptions!B23)*Assumptions!B20),Assumptions!B21) | K13: =MIN(Assumptions!B19+((10-Assumptions!B23)*Assumptions!B20),Assumptions!B21) | L13: =MIN(Assumptions!B19+((11-Assumptions!B23)*Assumptions!B20),Assumptions!B21) | M13: =MIN(Assumptions!B19+((12-Assumptions!B23)*Assumptions!B20),Assumptions!B21) | N13: =MIN(Assumptions!B19+((13-Assumptions!B23)*Assumptions!B20),Assumptions!B21) | O13: =MIN(Assumptions!B19+((14-Assumptions!B23)*Assumptions!B20),Assumptions!B21) | P13: =MIN(Assumptions!B19+((15-Assumptions!B23)*Assumptions!B20),Assumptions!B21) | Q13: =MIN(Assumptions!B19+((16-Assumptions!B23)*Assumptions!B20),Assumptions!B21) | R13: =MIN(Assumptions!B19+((17-Assumptions!B23)*Assumptions!B20),Assumptions!B21) | S13: =MIN(Assumptions!B19+((18-Assumptions!B23)*Assumptions!B20),Assumptions!B21)
A14: D2C Pro subscribers | B14: =ROUND((B9-B16)*B13,0) | C14: =ROUND((C9-C16)*C13,0) | D14: =ROUND((D9-D16)*D13,0) | E14: =ROUND((E9-E16)*E13,0) | F14: =ROUND((F9-F16)*F13,0) | G14: =ROUND((G9-G16)*G13,0) | H14: =ROUND((H9-H16)*H13,0) | I14: =ROUND((I9-I16)*I13,0) | ... S14: =ROUND((S9-S16)*S13,0)
A15: B2B conversion rate | B15: 0 | C15: 0 | D15: 0 | E15: =Assumptions!B22 | F15: =Assumptions!B22 | G15: =Assumptions!B22 | H15: =Assumptions!B22 | I15: =Assumptions!B22 | J15: =Assumptions!B22 | K15: =Assumptions!B22 | L15: =Assumptions!B22 | M15: =Assumptions!B22 | N15: =Assumptions!B22 | O15: =Assumptions!B22 | P15: =Assumptions!B22 | Q15: =Assumptions!B22 | R15: =Assumptions!B22 | S15: =Assumptions!B22
A16: Cumulative B2B users | B16: =B6 | C16: =B16+C6 | D16: =C16+D6 | E16: =D16+E6 | F16: =E16+F6 | G16: =F16+G6 | H16: =G16+H6 | I16: =H16+I6 | J16: =I16+J6 | ... S16: =R16+S6
A17: B2B Pro subscribers | B17: =ROUND(B16*B15,0) | C17: =ROUND(C16*C15,0) | D17: =ROUND(D16*D15,0) | E17: =ROUND(E16*E15,0) | F17: =ROUND(F16*F15,0) | G17: =ROUND(G16*G15,0) | H17: =ROUND(H16*H15,0) | I17: =ROUND(I16*I15,0) | ... S17: =ROUND(S16*S15,0)
A18: Total Pro subscribers | B18: =B14+B17 | C18: =C14+C17 | D18: =D14+D17 | E18: =E14+E17 | F18: =F14+F17 | G18: =G14+G17 | H18: =H14+H17 | I18: =I14+I17 | ... S18: =S14+S17
A19: Monetization active | B19: =IF(1>=Assumptions!B23,"YES","NO") | C19: =IF(2>=Assumptions!B23,"YES","NO") | D19: =IF(3>=Assumptions!B23,"YES","NO") | E19: =IF(4>=Assumptions!B23,"YES","NO") | F19: =IF(5>=Assumptions!B23,"YES","NO") | G19: =IF(6>=Assumptions!B23,"YES","NO") | H19: =IF(7>=Assumptions!B23,"YES","NO") | I19: =IF(8>=Assumptions!B23,"YES","NO") | J19: =IF(9>=Assumptions!B23,"YES","NO") | K19: =IF(10>=Assumptions!B23,"YES","NO") | L19: =IF(11>=Assumptions!B23,"YES","NO") | M19: =IF(12>=Assumptions!B23,"YES","NO") | N19: =IF(13>=Assumptions!B23,"YES","NO") | O19: =IF(14>=Assumptions!B23,"YES","NO") | P19: =IF(15>=Assumptions!B23,"YES","NO") | Q19: =IF(16>=Assumptions!B23,"YES","NO") | R19: =IF(17>=Assumptions!B23,"YES","NO") | S19: =IF(18>=Assumptions!B23,"YES","NO")
A20: D2C gross revenue | B20: =IF(B19="YES",B14*(Assumptions!B5/12),0) | C20: =IF(C19="YES",C14*(Assumptions!B5/12),0) | D20: =IF(D19="YES",D14*(Assumptions!B5/12),0) | E20: =IF(E19="YES",E14*(Assumptions!B5/12),0) | F20: =IF(F19="YES",F14*(Assumptions!B5/12),0) | G20: =IF(G19="YES",G14*(Assumptions!B5/12),0) | H20: =IF(H19="YES",H14*(Assumptions!B5/12),0) | I20: =IF(I19="YES",I14*(Assumptions!B5/12),0) | J20: =IF(J19="YES",J14*(Assumptions!B5/12),0) | K20: =IF(K19="YES",K14*(Assumptions!B5/12),0) | L20: =IF(L19="YES",L14*(Assumptions!B5/12),0) | M20: =IF(M19="YES",M14*(Assumptions!B5/12),0) | N20: =IF(N19="YES",N14*(Assumptions!B5/12),0) | O20: =IF(O19="YES",O14*(Assumptions!B5/12),0) | P20: =IF(P19="YES",P14*(Assumptions!B5/12),0) | Q20: =IF(Q19="YES",Q14*(Assumptions!B5/12),0) | R20: =IF(R19="YES",R14*(Assumptions!B5/12),0) | S20: =IF(S19="YES",S14*(Assumptions!B5/12),0)
A21: B2B gross revenue | B21: =IF(B19="YES",B17*(Assumptions!B8/12),0) | C21: =IF(C19="YES",C17*(Assumptions!B8/12),0) | D21: =IF(D19="YES",D17*(Assumptions!B8/12),0) | E21: =IF(E19="YES",E17*(Assumptions!B8/12),0) | F21: =IF(F19="YES",F17*(Assumptions!B8/12),0) | G21: =IF(G19="YES",G17*(Assumptions!B8/12),0) | H21: =IF(H19="YES",H17*(Assumptions!B8/12),0) | I21: =IF(I19="YES",I17*(Assumptions!B8/12),0) | J21: =IF(J19="YES",J17*(Assumptions!B8/12),0) | K21: =IF(K19="YES",K17*(Assumptions!B8/12),0) | L21: =IF(L19="YES",L17*(Assumptions!B8/12),0) | M21: =IF(M19="YES",M17*(Assumptions!B8/12),0) | N21: =IF(N19="YES",N17*(Assumptions!B8/12),0) | O21: =IF(O19="YES",O17*(Assumptions!B8/12),0) | P21: =IF(P19="YES",P17*(Assumptions!B8/12),0) | Q21: =IF(Q19="YES",Q17*(Assumptions!B8/12),0) | R21: =IF(R19="YES",R17*(Assumptions!B8/12),0) | S21: =IF(S19="YES",S17*(Assumptions!B8/12),0)
A22: Total gross revenue | B22: =B20+B21 | C22: =C20+C21 | D22: =D20+D21 | E22: =E20+E21 | F22: =F20+F21 | G22: =G20+G21 | H22: =H20+H21 | I22: =I20+I21 | ... S22: =S20+S21
A23: Gateway fees | B23: =ROUND(B22*Assumptions!B30,0) | C23: =ROUND(C22*Assumptions!B30,0) | D23: =ROUND(D22*Assumptions!B30,0) | E23: =ROUND(E22*Assumptions!B30,0) | F23: =ROUND(F22*Assumptions!B30,0) | G23: =ROUND(G22*Assumptions!B30,0) | H23: =ROUND(H22*Assumptions!B30,0) | I23: =ROUND(I22*Assumptions!B30,0) | J23: =ROUND(J22*Assumptions!B30,0) | K23: =ROUND(K22*Assumptions!B30,0) | L23: =ROUND(L22*Assumptions!B30,0) | M23: =ROUND(M22*Assumptions!B30,0) | N23: =ROUND(N22*Assumptions!B30,0) | O23: =ROUND(O22*Assumptions!B30,0) | P23: =ROUND(P22*Assumptions!B30,0) | Q23: =ROUND(Q22*Assumptions!B30,0) | R23: =ROUND(R22*Assumptions!B30,0) | S23: =ROUND(S22*Assumptions!B30,0)
A24: Net revenue | B24: =B22-B23 | C24: =C22-C23 | D24: =D22-D23 | E24: =E22-E23 | F24: =F22-F23 | G24: =G22-G23 | H24: =H22-H23 | I24: =I22-I23 | ... S24: =S22-S23
A26: EXPENSES
A27: Infrastructure | B27: =Assumptions!B39 | C27: =Assumptions!B39 | D27: =Assumptions!B39 | E27: =Assumptions!B39 | F27: =Assumptions!B39 | G27: =Assumptions!B39 | H27: =Assumptions!B39 | I27: =Assumptions!B39 | J27: =Assumptions!B39 | K27: =Assumptions!B39 | L27: =Assumptions!B39 | M27: =Assumptions!B39 | N27: =Assumptions!B39 | O27: =Assumptions!B39 | P27: =Assumptions!B39 | Q27: =Assumptions!B39 | R27: =Assumptions!B39 | S27: =Assumptions!B39
A28: Marketing & ads | B28: 0 | C28: 0 | D28: =MIN(Assumptions!B43+(3-Assumptions!B42)*Assumptions!B44,Assumptions!B45) | E28: =MIN(Assumptions!B43+(4-Assumptions!B42)*Assumptions!B44,Assumptions!B45) | F28: =MIN(Assumptions!B43+(5-Assumptions!B42)*Assumptions!B44,Assumptions!B45) | G28: =MIN(Assumptions!B43+(6-Assumptions!B42)*Assumptions!B44,Assumptions!B45) | H28: =MIN(Assumptions!B43+(7-Assumptions!B42)*Assumptions!B44,Assumptions!B45) | I28: =MIN(Assumptions!B43+(8-Assumptions!B42)*Assumptions!B44,Assumptions!B45) | J28: =MIN(Assumptions!B43+(9-Assumptions!B42)*Assumptions!B44,Assumptions!B45) | K28: =MIN(Assumptions!B43+(10-Assumptions!B42)*Assumptions!B44,Assumptions!B45) | L28: =MIN(Assumptions!B43+(11-Assumptions!B42)*Assumptions!B44,Assumptions!B45) | M28: =MIN(Assumptions!B43+(12-Assumptions!B42)*Assumptions!B44,Assumptions!B45) | N28: =MIN(Assumptions!B43+(13-Assumptions!B42)*Assumptions!B44,Assumptions!B45) | O28: =MIN(Assumptions!B43+(14-Assumptions!B42)*Assumptions!B44,Assumptions!B45) | P28: =MIN(Assumptions!B43+(15-Assumptions!B42)*Assumptions!B44,Assumptions!B45) | Q28: =MIN(Assumptions!B43+(16-Assumptions!B42)*Assumptions!B44,Assumptions!B45) | R28: =MIN(Assumptions!B43+(17-Assumptions!B42)*Assumptions!B44,Assumptions!B45) | S28: =MIN(Assumptions!B43+(18-Assumptions!B42)*Assumptions!B44,Assumptions!B45)
A29: B2B partnership costs | B29: 0 | C29: 0 | D29: 0 | E29: =Assumptions!B46 | F29: =Assumptions!B46 | G29: =Assumptions!B46 | H29: =Assumptions!B46 | I29: =Assumptions!B46 | J29: =Assumptions!B46 | K29: =Assumptions!B46 | L29: =Assumptions!B46 | M29: =Assumptions!B46 | N29: =Assumptions!B46 | O29: =Assumptions!B46 | P29: =Assumptions!B46 | Q29: =Assumptions!B46 | R29: =Assumptions!B46 | S29: =Assumptions!B46
A30: Content creation | B30: 0 | C30: 0 | D30: =Assumptions!B47 | E30: =Assumptions!B47 | F30: =Assumptions!B47 | G30: =Assumptions!B47 | H30: =Assumptions!B47 | I30: =Assumptions!B47 | J30: =Assumptions!B47 | K30: =Assumptions!B47 | L30: =Assumptions!B47 | M30: =Assumptions!B47 | N30: =Assumptions!B47 | O30: =Assumptions!B47 | P30: =Assumptions!B47 | Q30: =Assumptions!B47 | R30: =Assumptions!B47 | S30: =Assumptions!B47
A31: Total expenses | B31: =B27+B28+B29+B30 | C31: =C27+C28+C29+C30 | D31: =D27+D28+D29+D30 | E31: =E27+E28+E29+E30 | F31: =F27+F28+F29+F30 | G31: =G27+G28+G29+G30 | H31: =H27+H28+H29+H30 | I31: =I27+I28+I29+I30 | ... S31: =S27+S28+S29+S30
A33: PROFIT / LOSS
A34: Monthly profit/loss | B34: =B24-B31 | C34: =C24-C31 | D34: =D24-D31 | E34: =E24-E31 | F34: =F24-F31 | G34: =G24-G31 | H34: =H24-H31 | I34: =I24-I31 | ... S34: =S24-S31
A35: Cumulative profit/loss | B35: =B34 | C35: =B35+C34 | D35: =C35+D34 | E35: =D35+E34 | F35: =E35+F34 | G35: =F35+G34 | H35: =G35+H34 | I35: =H35+I34 | J35: =I35+J34 | ... S35: =R35+S34
A36: Profit margin | B36: =IF(B24>0,B34/B24,0) | C36: =IF(C24>0,C34/C24,0) | D36: =IF(D24>0,D34/D24,0) | E36: =IF(E24>0,E34/E24,0) | F36: =IF(F24>0,F34/F24,0) | G36: =IF(G24>0,G34/G24,0) | H36: =IF(H24>0,H34/H24,0) | I36: =IF(I24>0,I34/I24,0) | ... S36: =IF(S24>0,S34/S24,0)
A37: Breakeven reached? | B37: =IF(B35>0,"✓ YES","NO") | C37: =IF(C35>0,"✓ YES","NO") | D37: =IF(D35>0,"✓ YES","NO") | E37: =IF(E35>0,"✓ YES","NO") | F37: =IF(F35>0,"✓ YES","NO") | G37: =IF(G35>0,"✓ YES","NO") | H37: =IF(H35>0,"✓ YES","NO") | I37: =IF(I35>0,"✓ YES","NO") | ... S37: =IF(S35>0,"✓ YES","NO")

Sheet Summary
A1: KutumbKosh — Executive Summary (v2)
A3: QUARTERLY SNAPSHOTS
A4: Metric | B4: M3 | C4: M6 | D4: M9 | E4: M12 | F4: M15 | G4: M18
A5: Total users | B5: ='Growth Model'!D9 | C5: ='Growth Model'!G9 | D5: ='Growth Model'!J9 | E5: ='Growth Model'!M9 | F5: ='Growth Model'!P9 | G5: ='Growth Model'!S9
A6: Pro subscribers | B6: ='Growth Model'!D18 | C6: ='Growth Model'!G18 | D6: ='Growth Model'!J18 | E6: ='Growth Model'!M18 | F6: ='Growth Model'!P18 | G6: ='Growth Model'!S18
A7: Monthly net revenue | B7: ='Growth Model'!D24 | C7: ='Growth Model'!G24 | D7: ='Growth Model'!J24 | E7: ='Growth Model'!M24 | F7: ='Growth Model'!P24 | G7: ='Growth Model'!S24
A8: Monthly expenses | B8: ='Growth Model'!D31 | C8: ='Growth Model'!G31 | D8: ='Growth Model'!J31 | E8: ='Growth Model'!M31 | F8: ='Growth Model'!P31 | G8: ='Growth Model'!S31
A9: Monthly profit | B9: ='Growth Model'!D34 | C9: ='Growth Model'!G34 | D9: ='Growth Model'!J34 | E9: ='Growth Model'!M34 | F9: ='Growth Model'!P34 | G9: ='Growth Model'!S34
A10: Cumulative profit | B10: ='Growth Model'!D35 | C10: ='Growth Model'!G35 | D10: ='Growth Model'!J35 | E10: ='Growth Model'!M35 | F10: ='Growth Model'!P35 | G10: ='Growth Model'!S35
A11: Profit margin | B11: ='Growth Model'!D36 | C11: ='Growth Model'!G36 | D11: ='Growth Model'!J36 | E11: ='Growth Model'!M36 | F11: ='Growth Model'!P36 | G11: ='Growth Model'!S36
A14: 18-MONTH TOTALS
A15: Metric | B15: Amount
A16: Total gross revenue | B16: =SUM('Growth Model'!B22:S22)
A17: Total gateway fees | B17: =SUM('Growth Model'!B23:S23)
A18: Total net revenue | B18: =SUM('Growth Model'!B24:S24)
A19: Total infrastructure | B19: =SUM('Growth Model'!B27:S27)
A20: Total marketing | B20: =SUM('Growth Model'!B28:S28)
A21: Total B2B costs | B21: =SUM('Growth Model'!B29:S29)
A22: Total content costs | B22: =SUM('Growth Model'!B30:S30)
A23: Total expenses | B23: =SUM('Growth Model'!B31:S31)
A24: Net profit (18 months) | B24: ='Growth Model'!S35
A27: BUSINESS STRATEGY PHASES
A28: M1-M2: Launch & Build | B28: Free-only. Build user base, gather feedback, polish UX
A29: M3-M4: Monetize & Market | B29: Enable payments, start ad spend, launch B2B outreach to CAs
A30: M5-M8: Growth Engine | B30: Scale both D2C and B2B channels, optimize conversion funnels
A31: M9-M12: Scale & Optimize | B31: Reduce churn, increase ARPU, launch Family plan upsell
A32: M13-M15: Market Expansion | B32: NRI segment, regional languages, advanced features
A33: M18+: Profitability | B33: Target ₹1L+ monthly profit, consider seed round or stay bootstrapped

Sheet Scenarios
A1: KutumbKosh — Scenario Analysis
B3: Conservative | C3: Base Case | D3: Optimistic
A4: Annual price | B4: ₹499 | C4: ₹499 | D4: ₹499 + Family ₹799
A5: Launch signups | B5: 250 | C5: 400 | D5: 600
A6: Monthly growth rate | B6: 12% | C6: 20% | D6: 28%
A7: Churn rate | B7: 5% | C7: 3% | D7: 2%
A8: D2C conversion (initial) | B8: 2% | C8: 3% | D8: 5%
A9: B2B start month | B9: M6 | C9: M4 | D9: M3
A10: B2B monthly users | B10: 50 | C10: 100 | D10: 200
A11: Marketing budget (max) | B11: ₹15K/mo | C11: ₹25K/mo | D11: ₹40K/mo
A13: M18 total users | B13: ~15,000 | C13: ~55,000 | D13: ~120,000
A14: M18 Pro subscribers | B14: ~500 | C14: ~4,500 | D14: ~12,000
A15: M18 monthly net revenue | B15: ~₹18K | C15: ~₹1.5L | D15: ~₹5L
A16: 18-month cumulative profit | B16: ~₹50K | C16: ~₹6-8L | D16: ~₹25L+
A17: Breakeven month | B17: M8-M10 | C17: M4-M5 | D17: M3
